Workbook

Sheet Inputs
A1: CHAVE | B1: VALOR
A2: CLIENTE_NOME
A3: CLIENTE_ENDERECO_LOGRADOURO
A4: CLIENTE_BAIRRO_MUN_UF_CEP
A5: LOCAL_CIDADE_UF
A6: MES
A7: ANO
A8: UC_CONTA_CONTRATO
A9: UC_CLASSE | B9: B1
A10: COORD_SUL | B10: -22.803281
A11: COORD_OESTE | B11: -43.398319
A12: FV_POT_KWP
A13: MOD_MARCA
A14: MOD_MODELO
A15: MOD_QTD
A16: MOD_WP
A17: MOD_EFIC
A18: MOD_VMP
A19: MOD_IMP
A20: MOD_VOC
A21: MOD_ISC
A22: MOD_VSYS_MAX
A23: MOD_FUSIVEL_MAX
... A25: INV_MODELO
A26: INV_QTD | B26: 1
A27: INV_PN_KW
A28: INV_PMAXCC_KW
A29: INV_VCC_MAX
A30: INV_ICC_MAX
A31: INV_VMPPT_MAX
A32: INV_VMPPT_MIN
A33: INV_VSTART
A34: INV_STRINGS
A35: INV_MPPTS
A36: INV_PCA_KW
A37: INV_IMAX_CA
A38: INV_VAC_NOM | B38: 220
A39: INV_FN | B39: 60
A40: INV_FP
A41: INV_CONEXAO
...

Sheet Consumo_24m
A1: MES | B1: CONSUMO_KWH
A2: MÊS 1
A3: MÊS 2
A4: MÊS 3
A5: MÊS 4
A6: MÊS 5
A7: MÊS 6
A8: MÊS 7
A9: MÊS 8
A10: MÊS 9
A11: MÊS 10
A12: MÊS 11
A13: MÊS 12
... A25: MÊS 24
A26: TOTAL | B26: =SUM(B2:B25) -> 0
A27: MÉDIA | B27: =AVERAGE(B2:B25) -> #DIV/0!

Sheet Cargas_24
A1: ITEM | B1: DESCRICAO | C1: P_W | D1: QTD | E1: FP | F1: CI_KW | G1: CI_KVA
A2: 1 | F2: =IF(OR(C2="",D2=""),"",C2*D2/1000) | G2: =IF(OR(F2="",E2=""),"",F2/E2)
A3: 2 | F3: =IF(OR(C3="",D3=""),"",C3*D3/1000) | G3: =IF(OR(F3="",E3=""),"",F3/E3)
A4: 3 | F4: =IF(OR(C4="",D4=""),"",C4*D4/1000) | G4: =IF(OR(F4="",E4=""),"",F4/E4)
A5: 4 | F5: =IF(OR(C5="",D5=""),"",C5*D5/1000) | G5: =IF(OR(F5="",E5=""),"",F5/E5)
A6: 5 | F6: =IF(OR(C6="",D6=""),"",C6*D6/1000) | G6: =IF(OR(F6="",E6=""),"",F6/E6)
A7: 6 | F7: =IF(OR(C7="",D7=""),"",C7*D7/1000) | G7: =IF(OR(F7="",E7=""),"",F7/E7)
A8: 7 | F8: =IF(OR(C8="",D8=""),"",C8*D8/1000) | G8: =IF(OR(F8="",E8=""),"",F8/E8)
A9: 8 | F9: =IF(OR(C9="",D9=""),"",C9*D9/1000) | G9: =IF(OR(F9="",E9=""),"",F9/E9)
A10: 9 | F10: =IF(OR(C10="",D10=""),"",C10*D10/1000) | G10: =IF(OR(F10="",E10=""),"",F10/E10)
A11: 10 | F11: =IF(OR(C11="",D11=""),"",C11*D11/1000) | G11: =IF(OR(F11="",E11=""),"",F11/E11)
A12: 11 | F12: =IF(OR(C12="",D12=""),"",C12*D12/1000) | G12: =IF(OR(F12="",E12=""),"",F12/E12)
A13: 12 | F13: =IF(OR(C13="",D13=""),"",C13*D13/1000) | G13: =IF(OR(F13="",E13=""),"",F13/E13)
... A25: 24 | F25: =IF(OR(C25="",D25=""),"",C25*D25/1000) | G25: =IF(OR(F25="",E25=""),"",F25/E25)
A26: TOTAL | F26: =SUM(F2:F25) -> 0 | G26: =SUM(G2:G25) -> 0

Sheet Calculos
A1: VAR | B1: VALOR
A2: FV_POT_STC_KWP | B2: =Inputs!B15*Inputs!B16/1000 -> 0
A3: FV_POT_VI_W | B3: =Inputs!B18*Inputs!B19*Inputs!B15 -> 0
A4: VCC_NOM | B4: =Inputs!B18*Inputs!B15 -> 0
A5: ICC_MAX | B5: =Inputs!B19 -> 0
A6: IAC_MAX | B6: =Inputs!B36*1000/Inputs!B38 -> 0
A7: DV_CC_V | B7: =Inputs!B19*Inputs!B49*(2*Inputs!B43/1000) -> 0
A8: DV_CC_PERC | B8: =IF(B4=0,"",B7/B4)
A9: DV_CA_V | B9: =B6*Inputs!B50*(2*Inputs!B44/1000) -> 0
A10: DV_CA_PERC | B10: =IF(Inputs!B38=0,"",B9/Inputs!B38) -> 0

Sheet Mapeamento
A1: PLACEHOLDER | B1: ORIGEM
A2: {{CLIENTE_NOME}} | B2: Inputs!B2
A3: {{CLIENTE_ENDERECO_LOGRADOURO}} | B3: Inputs!B3
A4: {{CLIENTE_BAIRRO_MUN_UF_CEP}} | B4: Inputs!B4
A5: {{LOCAL_CIDADE_UF}} | B5: Inputs!B5
A6: {{MES}} | B6: Inputs!B6
A7: {{ANO}} | B7: Inputs!B7
A8: {{UC_CONTA_CONTRATO}} | B8: Inputs!B8
A9: {{UC_CLASSE}} | B9: Inputs!B9
A10: {{COORD_SUL}} | B10: Inputs!B10
A11: {{COORD_OESTE}} | B11: Inputs!B11
A12: {{FV_POT_KWP}} | B12: Inputs!B12
... A231: {{CARGA_TOTAL_KVA}} | B231: Cargas_24!G26
